2023-11-30 19:25:23,405 INFO    MainThread:42525 [wandb_setup.py:_flush():76] Current SDK version is 0.16.0
2023-11-30 19:25:23,405 INFO    MainThread:42525 [wandb_setup.py:_flush():76] Configure stats pid to 42525
2023-11-30 19:25:23,405 INFO    MainThread:42525 [wandb_setup.py:_flush():76] Loading settings from /Users/owendugan/.config/wandb/settings
2023-11-30 19:25:23,405 INFO    MainThread:42525 [wandb_setup.py:_flush():76] Loading settings from /Users/owendugan/Documents/GitHub/Gym-Snake/wandb/settings
2023-11-30 19:25:23,405 INFO    MainThread:42525 [wandb_setup.py:_flush():76] Loading settings from environment variables: {}
2023-11-30 19:25:23,405 INFO    MainThread:42525 [wandb_setup.py:_flush():76] Applying setup settings: {'_disable_service': False}
2023-11-30 19:25:23,405 INFO    MainThread:42525 [wandb_setup.py:_flush():76] Inferring run settings from compute environment: {'program_relpath': 'ppo.py', 'program_abspath': '/Users/owendugan/Documents/GitHub/Gym-Snake/ppo.py', 'program': '/Users/owendugan/Documents/GitHub/Gym-Snake/ppo.py'}
2023-11-30 19:25:23,405 INFO    MainThread:42525 [wandb_init.py:_log_setup():524] Logging user logs to /Users/owendugan/Documents/GitHub/Gym-Snake/wandb/run-20231130_192523-j8sjw3gc/logs/debug.log
2023-11-30 19:25:23,405 INFO    MainThread:42525 [wandb_init.py:_log_setup():525] Logging internal logs to /Users/owendugan/Documents/GitHub/Gym-Snake/wandb/run-20231130_192523-j8sjw3gc/logs/debug-internal.log
2023-11-30 19:25:23,406 INFO    MainThread:42525 [wandb_init.py:init():564] calling init triggers
2023-11-30 19:25:23,406 INFO    MainThread:42525 [wandb_init.py:init():571] wandb.init called with sweep_config: {}
config: {'exp_name': 'ppo', 'seed': 1, 'torch_deterministic': True, 'cuda': False, 'track': True, 'wandb_project_name': 'cleanRL', 'wandb_entity': None, 'capture_video': False, 'env_id': 'BreakoutNoFrameskip-v4', 'total_timesteps': 10000000, 'learning_rate': 0.00025, 'num_envs': 8, 'num_steps': 128, 'anneal_lr': True, 'gamma': 0.99, 'gae_lambda': 0.95, 'num_minibatches': 4, 'update_epochs': 4, 'norm_adv': True, 'clip_coef': 0.1, 'clip_vloss': True, 'ent_coef': 0.01, 'vf_coef': 0.5, 'max_grad_norm': 0.5, 'target_kl': None, 'batch_size': 1024, 'minibatch_size': 256, 'num_iterations': 9765}
2023-11-30 19:25:23,406 INFO    MainThread:42525 [wandb_init.py:init():614] starting backend
2023-11-30 19:25:23,406 INFO    MainThread:42525 [wandb_init.py:init():618] setting up manager
2023-11-30 19:25:23,407 INFO    MainThread:42525 [backend.py:_multiprocessing_setup():105] multiprocessing start_methods=spawn,fork,forkserver, using: spawn
2023-11-30 19:25:23,409 INFO    MainThread:42525 [wandb_init.py:init():624] backend started and connected
2023-11-30 19:25:23,413 INFO    MainThread:42525 [wandb_init.py:init():716] updated telemetry
2023-11-30 19:25:23,452 INFO    MainThread:42525 [wandb_init.py:init():749] communicating run to backend with 90.0 second timeout
2023-11-30 19:25:33,816 INFO    Thread-1 (wrapped_target):42525 [retry.py:__call__():172] Retry attempt failed:
Traceback (most recent call last):
  File "/Users/owendugan/mambaforge/envs/snake/lib/python3.10/site-packages/urllib3/connection.py", line 203, in _new_conn
    sock = connection.create_connection(
  File "/Users/owendugan/mambaforge/envs/snake/lib/python3.10/site-packages/urllib3/util/connection.py", line 60, in create_connection
    for res in socket.getaddrinfo(host, port, family, socket.SOCK_STREAM):
  File "/Users/owendugan/mambaforge/envs/snake/lib/python3.10/socket.py", line 955, in getaddrinfo
    for res in _socket.getaddrinfo(host, port, family, type, proto, flags):
socket.gaierror: [Errno 8] nodename nor servname provided, or not known

The above exception was the direct cause of the following exception:

Traceback (most recent call last):
  File "/Users/owendugan/mambaforge/envs/snake/lib/python3.10/site-packages/urllib3/connectionpool.py", line 790, in urlopen
    response = self._make_request(
  File "/Users/owendugan/mambaforge/envs/snake/lib/python3.10/site-packages/urllib3/connectionpool.py", line 491, in _make_request
    raise new_e
  File "/Users/owendugan/mambaforge/envs/snake/lib/python3.10/site-packages/urllib3/connectionpool.py", line 467, in _make_request
    self._validate_conn(conn)
  File "/Users/owendugan/mambaforge/envs/snake/lib/python3.10/site-packages/urllib3/connectionpool.py", line 1096, in _validate_conn
    conn.connect()
  File "/Users/owendugan/mambaforge/envs/snake/lib/python3.10/site-packages/urllib3/connection.py", line 611, in connect
    self.sock = sock = self._new_conn()
  File "/Users/owendugan/mambaforge/envs/snake/lib/python3.10/site-packages/urllib3/connection.py", line 210, in _new_conn
    raise NameResolutionError(self.host, self, e) from e
urllib3.exceptions.NameResolutionError: <urllib3.connection.HTTPSConnection object at 0x168e0d0c0>: Failed to resolve 'api.wandb.ai' ([Errno 8] nodename nor servname provided, or not known)

The above exception was the direct cause of the following exception:

Traceback (most recent call last):
  File "/Users/owendugan/mambaforge/envs/snake/lib/python3.10/site-packages/requests/adapters.py", line 486, in send
    resp = conn.urlopen(
  File "/Users/owendugan/mambaforge/envs/snake/lib/python3.10/site-packages/urllib3/connectionpool.py", line 844, in urlopen
    retries = retries.increment(
  File "/Users/owendugan/mambaforge/envs/snake/lib/python3.10/site-packages/urllib3/util/retry.py", line 515, in increment
    raise MaxRetryError(_pool, url, reason) from reason  # type: ignore[arg-type]
urllib3.exceptions.MaxRetryError: HTTPSConnectionPool(host='api.wandb.ai', port=443): Max retries exceeded with url: /graphql (Caused by NameResolutionError("<urllib3.connection.HTTPSConnection object at 0x168e0d0c0>: Failed to resolve 'api.wandb.ai' ([Errno 8] nodename nor servname provided, or not known)"))

During handling of the above exception, another exception occurred:

Traceback (most recent call last):
  File "/Users/owendugan/mambaforge/envs/snake/lib/python3.10/site-packages/wandb/sdk/lib/retry.py", line 131, in __call__
    result = self._call_fn(*args, **kwargs)
  File "/Users/owendugan/mambaforge/envs/snake/lib/python3.10/site-packages/wandb/sdk/internal/internal_api.py", line 366, in execute
    return self.client.execute(*args, **kwargs)  # type: ignore
  File "/Users/owendugan/mambaforge/envs/snake/lib/python3.10/site-packages/wandb/vendor/gql-0.2.0/wandb_gql/client.py", line 52, in execute
    result = self._get_result(document, *args, **kwargs)
  File "/Users/owendugan/mambaforge/envs/snake/lib/python3.10/site-packages/wandb/vendor/gql-0.2.0/wandb_gql/client.py", line 60, in _get_result
    return self.transport.execute(document, *args, **kwargs)
  File "/Users/owendugan/mambaforge/envs/snake/lib/python3.10/site-packages/wandb/sdk/lib/gql_request.py", line 58, in execute
    request = self.session.post(self.url, **post_args)
  File "/Users/owendugan/mambaforge/envs/snake/lib/python3.10/site-packages/requests/sessions.py", line 637, in post
    return self.request("POST", url, data=data, json=json, **kwargs)
  File "/Users/owendugan/mambaforge/envs/snake/lib/python3.10/site-packages/requests/sessions.py", line 589, in request
    resp = self.send(prep, **send_kwargs)
  File "/Users/owendugan/mambaforge/envs/snake/lib/python3.10/site-packages/requests/sessions.py", line 703, in send
    r = adapter.send(request, **kwargs)
  File "/Users/owendugan/mambaforge/envs/snake/lib/python3.10/site-packages/requests/adapters.py", line 519, in send
    raise ConnectionError(e, request=request)
requests.exceptions.ConnectionError: HTTPSConnectionPool(host='api.wandb.ai', port=443): Max retries exceeded with url: /graphql (Caused by NameResolutionError("<urllib3.connection.HTTPSConnection object at 0x168e0d0c0>: Failed to resolve 'api.wandb.ai' ([Errno 8] nodename nor servname provided, or not known)"))
2023-11-30 19:25:55,057 WARNING MainThread:42525 [wandb_init.py:init():1188] interrupted
Traceback (most recent call last):
  File "/Users/owendugan/mambaforge/envs/snake/lib/python3.10/site-packages/wandb/sdk/wandb_init.py", line 1166, in init
    run = wi.init()
  File "/Users/owendugan/mambaforge/envs/snake/lib/python3.10/site-packages/wandb/sdk/wandb_init.py", line 752, in init
    result = run_init_handle.wait(
  File "/Users/owendugan/mambaforge/envs/snake/lib/python3.10/site-packages/wandb/sdk/lib/mailbox.py", line 283, in wait
    found, abandoned = self._slot._get_and_clear(timeout=wait_timeout)
  File "/Users/owendugan/mambaforge/envs/snake/lib/python3.10/site-packages/wandb/sdk/lib/mailbox.py", line 130, in _get_and_clear
    if self._wait(timeout=timeout):
  File "/Users/owendugan/mambaforge/envs/snake/lib/python3.10/site-packages/wandb/sdk/lib/mailbox.py", line 126, in _wait
    return self._event.wait(timeout=timeout)
  File "/Users/owendugan/mambaforge/envs/snake/lib/python3.10/threading.py", line 607, in wait
    signaled = self._cond.wait(timeout)
  File "/Users/owendugan/mambaforge/envs/snake/lib/python3.10/threading.py", line 324, in wait
    gotit = waiter.acquire(True, timeout)
KeyboardInterrupt
